<?xml version="1.0"?>
<robot name="rb1_robot">

    <gazebo reference="base_link">
        <material>Gazebo/Blue</material>
    </gazebo>

    <gazebo reference="left_wheel">
        <mu1>0.8</mu1>
        <mu2>0.8</mu2>
        <material>Gazebo/Red</material>
    </gazebo>

    <gazebo reference="right_wheel">
        <mu1>0.8</mu1>
        <mu2>0.8</mu2>
        <material>Gazebo/Red</material>
    </gazebo>

    <gazebo reference="base_link_front_caster_joint">
        <preserveFixedJoint>true</preserveFixedJoint>
    </gazebo>

    <gazebo reference="base_link_back_caster_joint">
        <preserveFixedJoint>true</preserveFixedJoint>
    </gazebo>

    <gazebo reference="front_caster">
        <mu1>0</mu1>
        <mu2>0</mu2>
        <material>Gazebo/White</material>
    </gazebo>

    <gazebo reference="back_caster">
        <mu1>0</mu1>
        <mu2>0</mu2>
        <material>Gazebo/White</material>
    </gazebo>

    <gazebo reference="base_link_front_laser_joint">
        <preserveFixedJoint>true</preserveFixedJoint>
    </gazebo>

    <gazebo reference="front_laser">
        <material>Gazebo/Black</material>
    </gazebo>

    <gazebo reference="front_laser">
        <sensor type="ray" name="head_hokuyo_sensor">
            <pose>0 0 0 0 0 0</pose>
            <visualize>true</visualize>
            <update_rate>20</update_rate>
            <ray>
                <scan>
                    <horizontal>
                        <samples>720</samples>
                        <resolution>1</resolution>
                        <min_angle>-1.570796</min_angle>
                        <max_angle>1.570796</max_angle>
                    </horizontal>
                </scan>
                <range>
                    <min>0.04</min>
                    <max>5.0</max>
                    <resolution>0.01</resolution>
                </range>
                <noise>
                    <type>gaussian</type>
                    <mean>0.0</mean>
                    <stddev>0.01</stddev>
                </noise>
            </ray>
            <plugin name="gazebo_ros_head_hokuyo_controller" filename="libgazebo_ros_laser.so">
                <topicName>/scan</topicName>
                <frameName>sensor_laser</frameName>
            </plugin>
        </sensor>
    </gazebo>

    <gazebo>
        <plugin filename="libgazebo_ros_diff_drive.so" name="differential_drive_controller">
            <alwaysOn>true</alwaysOn>
            <updateRate>20</updateRate>
            <leftJoint>base_link_left_wheel_joint</leftJoint>
            <rightJoint>base_link_right_wheel_joint</rightJoint>
            <wheelSeparation>0.4</wheelSeparation>
            <wheelDiameter>0.05</wheelDiameter>
            <torque>0.25</torque>
            <commandTopic>cmd_vel</commandTopic>
            <odometryTopic>odom</odometryTopic>
            <odometryFrame>odom</odometryFrame>
            <robotBaseFrame>base_link</robotBaseFrame>
        </plugin>
    </gazebo>

    <link name="base_link">
        <inertial>
            <mass value="15.5"/>
            <origin xyz="0 0 0" rpy="0 0 0"/>
            <inertia ixx="0.3584375" ixy="0" ixz="0" iyy="0.3584375" iyz="0" izz="0.484375" />
        </inertial>

        <visual>
            <geometry>
                <cylinder length="0.3" radius="0.25"/>
            </geometry>
            <material name="Blue">
                <color rgba="0.2 0.2 0.8 1"/>
            </material>
        </visual>

        <collision>
            <geometry>
                <cylinder length="0.3" radius="0.25"/>
            </geometry>
        </collision>
    </link>

    <joint name="base_link_base_footprint_joint" type="fixed">
        <origin rpy="0 0 0" xyz="0.0 0.0 0.15" />
        <child link="base_link" />
        <parent link="base_footprint" />
        <joint_properties damping="1.0" friction="1.0" />
    </joint>

    <link name="base_footprint">
        <inertial>
            <mass value="0"/>
            <origin xyz="0 0 0" rpy="0 0 0"/>
            <inertia ixx="0" ixy="0" ixz="0" iyy="0" iyz="0" izz="0" />
        </inertial>
    </link>

    <joint name="base_link_left_wheel_joint" type="continuous">
        <origin rpy="0 0 0" xyz="0.0 0.2 -0.15" />
        <child link="left_wheel" />
        <parent link="base_link" /> 
        <axis rpy="0 0 0" xyz="0 1 0" />
        <limit effort="10000" velocity="1000" />
        <joint_properties damping="1.0" friction="1.0" />
    </joint>

    <link name="left_wheel">
        <inertial>
            <mass value="2.5"/>
            <origin xyz="0 0 0" rpy="0 0 0"/>
            <inertia ixx="0.00064583" ixy="0" ixz="0" iyy="0.00078125" iyz="0" izz="0.00064583" />
        </inertial>

        <visual>
            <origin xyz="0 0 0" rpy="1.5708 0 0"/>
            <geometry>
                <cylinder length="0.035" radius="0.025"/>
            </geometry>
            <material name="Red">
                <color rgba="0.8 0.2 0.2 1"/>
            </material>
        </visual>

        <collision>
            <origin xyz="0 0 0" rpy="1.5708 0 0"/>
            <geometry>
                <cylinder length="0.035" radius="0.025"/>
            </geometry>
        </collision>
    </link>

    <joint name="base_link_right_wheel_joint" type="continuous">
        <origin rpy="0 0 0" xyz="0.0 -0.2 -0.15" />
        <child link="right_wheel" />
        <parent link="base_link" /> 
        <axis rpy="0 0 0" xyz="0 1 0" />
        <limit effort="10000" velocity="1000" />
        <joint_properties damping="1.0" friction="1.0" />
    </joint>

    <link name="right_wheel">
        <inertial>
            <mass value="2.5"/>
            <origin xyz="0 0 0" rpy="0 0 0"/>
            <inertia ixx="0.00064583" ixy="0" ixz="0" iyy="0.00078125" iyz="0" izz="0.00064583" />
        </inertial>

        <visual>
            <origin xyz="0 0 0" rpy="1.5708 0 0"/>
            <geometry>
                <cylinder length="0.035" radius="0.025"/>
            </geometry>
            <material name="Red">
                <color rgba="0.8 0.2 0.2 1"/>
            </material>
        </visual>

        <collision>
            <origin xyz="0 0 0" rpy="1.5708 0 0"/>
            <geometry>
                <cylinder length="0.035" radius="0.025"/>
            </geometry>
        </collision>
    </link>

    <joint name="base_link_front_caster_joint" type="fixed">
        <origin rpy="0 0 0" xyz="0.1 0.0 -0.15" />
        <child link="front_caster" />
        <parent link="base_link" /> 
        <joint_properties damping="0.0" friction="0.0" />
    </joint>

    <link name="front_caster">
        <inertial>
            <mass value="1.5"/>
            <origin xyz="0 0 0" rpy="0 0 0"/>
            <inertia ixx="0.000375" ixy="0" ixz="0" iyy="0.000375" iyz="0" izz="0.000375" />
        </inertial>

        <visual>
            <geometry>	
                <sphere radius="0.025"/>
            </geometry>
            <material name="Grey">
                <color rgba="0.4 0.4 0.4 1" />
            </material>
        </visual>

        <collision>
            <geometry>	
                <sphere radius="0.025"/>
            </geometry>
        </collision>
    </link>

    <joint name="base_link_back_caster_joint" type="fixed">
        <origin rpy="0 0 0" xyz="-0.1 0.0 -0.15" />
        <child link="back_caster" />
        <parent link="base_link" /> 
        <joint_properties damping="0.0" friction="0.0" />
    </joint>

    <link name="back_caster">
        <inertial>
            <mass value="1.5"/>
            <origin xyz="0 0 0" rpy="0 0 0"/>
            <inertia ixx="0.000375" ixy="0" ixz="0" iyy="0.000375" iyz="0" izz="0.000375" />
        </inertial>

        <visual>
            <geometry>	
                <sphere radius="0.025"/>
            </geometry>
            <material name="Grey">
                <color rgba="0.4 0.4 0.4 1" />
            </material>
        </visual>

        <collision>
            <geometry>	
                <sphere radius="0.025"/>
            </geometry>
        </collision>
    </link>

    <joint name="base_link_front_laser_joint" type="fixed">
        <origin rpy="3.14159 0 0" xyz="0.25 0.0 0.075" />
        <child link="front_laser" />
        <parent link="base_link" /> 
        <joint_properties damping="0.0" friction="0.0" />
    </joint>

    <link name="front_laser">
        <inertial>
            <mass value="1.5"/>
            <origin xyz="0 0 0" rpy="0 0 0"/>
            <inertia ixx="0.0003875" ixy="0" ixz="0" iyy="0.0003875" iyz="0" izz="0.000675" />
        </inertial>

        <visual>
            <origin xyz="0 0 0" rpy="0 0 0"/>
            <geometry>
                <cylinder length="0.02" radius="0.03"/>
            </geometry>
            <material name="Black">
                <color rgba="0.1 0.1 0.1 1"/>
            </material>
        </visual>

        <collision>
            <origin xyz="0 0 0" rpy="0 0 0"/>
            <geometry>
                <cylinder length="0.02" radius="0.03"/>
            </geometry>
        </collision>
    </link>
</robot>